Workbook

Sheet Anleitung
A1: Kalkulation Rohrlaserteile – Version 0.1 (Schritt 1: Grundstruktur)
A2: Erstellt 15.10.2026. Optimierung (VBA), STEP-Import und Kostenrechnung folgen in Schritt 2–4.
A4: Farblegende
A5: Gelb / blaue Schrift | B5: Eingabefeld. Nur hier Werte eintragen.
A6: Grau / schwarze Schrift | B6: Berechnet (Formel). Nicht überschreiben.
A7: Grau / grüne Schrift | B7: Aus anderem Blatt nachgeschlagen (Formel). Nicht überschreiben.
A9: Blätter
A10: Auftrag | B10: Auftragskopf (Auftrag, Kunde, Maschine, Standard-Stangenlänge) und bis zu 500 Positionen. Spalte W zeigt je Zeile den Prüfstatus.
A11: Profile | B11: Profil-Stammdaten: Form, Abmessungen, Wandstärke, Querschnitt; optional profilspezifischer Endbeschnitt/Greiferrest.
A12: Werkstoffe | B12: Werkstoff/Materialqualität mit Dichte.
A13: Preise | B13: Materialpreis je Profil + Werkstoff, wahlweise €/kg oder €/Stange.
A14: Maschinen | B14: Maschinenparameter: Endbeschnitt, Greiferrest, Schnittverlust, max. Stangenlänge, Stundensatz.
A15: Schneiddaten | B15: Vorschub und Einstechzeit je Maschine, Werkstoff und Wandstärke (für Laserzeit in Schritt 4).
A16: Gewinde | B16: Kernlochdurchmesser je Gewinde. Der STEP-Import schlägt anhand dieser Tabelle Gewinde vor.
A17: STEP-Import | B17: Wird beim ersten STEP-Import angelegt: Protokoll aller Messwerte je Teil.
A18: Listen | B18: Auswahllisten (Profilform, Preisbasis).
A20: Arbeitsablauf
A21: 1. | B21: Stammdaten pflegen (Profile, Werkstoffe, Preise, Maschinen, Schneiddaten). Die vorhandenen Zeilen sind BEISPIELWERTE und müssen durch eigene Daten ersetzt werden.
A22: 2. | B22: Auftragskopf ausfüllen, Maschine wählen, Standard-Stangenlänge prüfen (Vorgabe 6.000 mm).
A23: 3. | B23: Positionen eintragen (Profil und Werkstoff per Auswahlliste). Schneidweg später automatisch per STEP-Import (Schritt 2).
A24: 4. | B24: Status-Spalte prüfen: FEHLER muss behoben werden, WARNUNG/HINWEIS sollte geprüft werden.
A26: Annahmen
A27: A1 | B27: Microsoft 365 / Excel 2019 oder neuer. Diese Version ist .xlsx ohne Makros; ab Schritt 3 wird sie zu .xlsm (Makros erforderlich).
A28: A2 | B28: Ein Auftrag je Blatt 'Auftrag'. Alle Positionen laufen auf der im Kopf gewählten Maschine.
A29: A3 | B29: Stangenlänge: Standard aus dem Auftragskopf, je Position abweichend überschreibbar (Spalte J).
A30: A4 | B30: Endbeschnitt und Greiferrest kommen von der Maschine; ist am Profil ein abweichender Wert eingetragen, gilt der Profilwert.
A31: A5 | B31: Nutzlänge je Stange = Stangenlänge − Endbeschnitt − Greiferrest. Ein Teil passt nur, wenn Teilelänge + Schnittverlust ≤ Nutzlänge (konservativ, genaue Regel folgt mit der Optimierung).
A32: A6 | B32: Querschnitt berechnet ohne Eckradien (Quadrat-/Rechteckrohr ca. 1–4 % zu schwer). Für exakte Gewichte den Herstellerwert in 'Fläche manuell' eintragen; Sonderprofile benötigen immer 'Fläche manuell'.
A33: A7 | B33: Metergewicht [kg/m] = Querschnitt [mm²] × Dichte [kg/dm³] / 1000.
A34: A8 | B34: Keine Restlagerverwaltung: Reststücke werden nur als Verschnitt ausgewiesen (Entscheidung vom 15.10.2026).
A35: A9 | B35: Kapazität: 300 Zeilen je Stammdatenblatt, 500 Auftragspositionen. Erweiterbar, indem Formelzeilen nach unten kopiert und die Namen in Formeln > Namens-Manager angepasst werden.
A36: A10 | B36: Einheiten: Längen in mm, Gewicht in kg, Preise in € netto.
A37: A11 | B37: Gemeinsamer Trennschnitt: Liegen zwei Teile auf der Stange nebeneinander und sind beide zugewandten Enden gerade (senkrecht), wird nur ein Schnitt gerechnet, sonst zwei. Dafür stehen je Teil Anfangs- und Endschnitt (gerade ja/nein, Schnittlänge) in Spalten Y–AB; Spalte H enthält immer beide Enden voll. Die Verrechnung erfolgt in der Optimierung (Schritt 3). Beim gemeinsamen Schnitt zählt auch der Schnittverlust nur einmal.
A38: A12 | B38: Schneidweg (Spalte H) = Anfangsschnitt + Endschnitt + Innenkonturen (AC). Gravuren (nicht durchgehende Konturen) stehen separat in AD und sind nicht im Schneidweg enthalten.
... A40: A14 | B40: Konturgröße: Innenkonturen werden nach ihrem größten Hüllmaß in klein / mittel / groß eingeteilt (AH–AM). Die Grenzen stehen je Maschine im Blatt 'Maschinen' (Vorgabe: klein ≤ 10 mm, mittel ≤ 50 mm, darüber groß). Anfangs- und Endschnitt werden nicht eingeteilt. Beim Import gilt die im Auftragskopf gewählte Maschine.

Sheet Auftrag
A1: Auftrag – Eingabe
A2: Kopf ausfüllen, dann Positionen ab Zeile 13. Status in Spalte W beachten. Beispielpositionen vor Gebrauch löschen (nur gelbe Zellen).
F3: Maschinenwerte (aus Blatt 'Maschinen') | J3: Übersicht
A4: Auftragsnummer | C4: A-2026-0001 | F4: Endbeschnitt [mm] | H4: =IF($C$8="","",IFERROR(INDEX(Maschinen!$C$5:$C$304,MATCH($C$8,lst_Maschine,0)),"?")) -> 20 | J4: Positionen | M4: =COUNTIF($W$13:$W$512,"?*") -> 5
A5: Kundennummer | C5: K-10045 | F5: Greiferrest [mm] | H5: =IF($C$8="","",IFERROR(INDEX(Maschinen!$D$5:$D$304,MATCH($C$8,lst_Maschine,0)),"?")) -> 80 | J5: davon FEHLER | M5: =COUNTIF($W$13:$W$512,"FEHLER*") -> 0
A6: Kundenname | C6: Beispiel GmbH | F6: Schnittverlust [mm] | H6: =IF($C$8="","",IFERROR(INDEX(Maschinen!$E$5:$E$304,MATCH($C$8,lst_Maschine,0)),"?")) -> 0.3 | J6: davon WARNUNG/HINWEIS | M6: =COUNTIF($W$13:$W$512,"WARNUNG*")+COUNTIF($W$13:$W$512,"HINWEIS*") -> 0
A7: Datum | C7: 46310 | F7: Max. Stangenlänge [mm] | H7: =IF($C$8="","",IFERROR(INDEX(Maschinen!$F$5:$F$304,MATCH($C$8,lst_Maschine,0)),"?")) -> 6500 | J7: Teile gesamt [Stk] | M7: =SUM($G$13:$G$512) -> 152
A8: Maschine | C8: RL-1 | F8: Stundensatz [€/h] | H8: =IF($C$8="","",IFERROR(INDEX(Maschinen!$G$5:$G$304,MATCH($C$8,lst_Maschine,0)),"?")) -> 120 | J8: Teilelänge gesamt [m] | M8: =SUM($P$13:$P$512)/1000 -> 139.628
A9: Standard-Stangenlänge [mm] | C9: 6000 | J9: Teilegewicht gesamt [kg] | M9: =SUM($X$13:$X$512) -> 406.09708
A12: Pos. | B12: Artikelnummer | C12: Bezeichnung | D12: Profil-ID | E12: Werkstoff-ID | F12: Teilelänge [mm] | G12: Stückzahl | H12: Schneidweg je Teil ohne Gravur [mm] (STEP) | I12: Einstiche je Teil (STEP) | J12: Stangenlänge abweichend [mm] | K12: Profilform | L12: Querschnitt [mm²] | M12: Wandstärke [mm] | N12: Metergewicht [kg/m] | O12: Gewicht je Teil [kg] | P12: Länge gesamt [mm] | Q12: Stangenlänge wirksam [mm] | R12: Endbeschnitt wirksam [mm] | S12: Greiferrest wirksam [mm] | T12: Nutzlänge Stange [mm] | U12: Preis hinterlegt | V12: Vorschub [mm/min] | W12: Status | X12: Gewicht Position [kg] | Y12: Anfangsschnitt gerade (STEP) | Z12: Anfangsschnitt [mm] (STEP) | AA12: Endschnitt gerade (STEP) | AB12: Endschnitt [mm] (STEP) | AC12: Innenkonturen [mm] (STEP) | AD12: Gravur [mm] (STEP) | AE12: Bohrungen (STEP) | AF12: Gewinde-Vorschlag (STEP) | AG12: Gewinde geprüft (manuell) | AH12: Kontur klein [Stk] (STEP) | AI12: Kontur klein [mm] (STEP) | AJ12: Kontur mittel [Stk] (STEP) | AK12: Kontur mittel [mm] (STEP) | AL12: Kontur groß [Stk] (STEP) | AM12: Kontur groß [mm] (STEP)
A13: 10 | B13: 4711-001 | C13: Holm links | D13: RR 42,4x2,0 | E13: S235-10219 | F13: 1250 | G13: 24 | H13: 410.5 | I13: 4 | K13: =IF($D13="","",IFERROR(INDEX(Profile!$B$5:$B$304,MATCH($D13,lst_Profil,0)),"")) -> Rundrohr | L13: =IF($D13="","",IFERROR(INDEX(Profile!$K$5:$K$304,MATCH($D13,lst_Profil,0))+0,"")) -> 253.84069 | M13: =IF($D13="","",IFERROR(INDEX(Profile!$E$5:$E$304,MATCH($D13,lst_Profil,0))+0,"")) -> 2 | N13: =IF(OR(L13="",$E13=""),"",IFERROR(L13*INDEX(Werkstoffe!$E$5:$E$304,MATCH($E13,lst_Werkstoff,0))/1000,"")) -> 1.9926494 | O13: =IF(OR(N13="",$F13=""),"",N13*$F13/1000) -> 2.4908117 | P13: =IF(OR($F13="",$G13=""),"",$F13*$G13) -> 30000 | Q13: =IF($D13="","",IF($J13<>"",$J13,$C$9)) -> 6000 | R13: =IF($D13="","",IFERROR(IF(INDEX(Profile!$G$5:$G$304,MATCH($D13,lst_Profil,0))<>"",INDEX(Profile!$G$5:$G$304,MATCH($D13,lst_Profil,0)),$H$4),$H$4)) -> 20 | S13: =IF($D13="","",IFERROR(IF(INDEX(Profile!$H$5:$H$304,MATCH($D13,lst_Profil,0))<>"",INDEX(Profile!$H$5:$H$304,MATCH($D13,lst_Profil,0)),$H$5),$H$5)) -> 80 | T13: =IF(OR(Q13="",NOT(ISNUMBER(R13)),NOT(ISNUMBER(S13))),"",Q13-R13-S13) -> 5900 | U13: =IF(OR($D13="",$E13=""),"",IF(COUNTIFS(Preise!$A$5:$A$304,$D13,Preise!$B$5:$B$304,$E13,Preise!$I$5:$I$304,"OK")>0,"ja","nein")) -> ja | V13: =IF(OR(M13="",$E13="",$C$8=""),"",IF(_xlfn.MINIFS(Schneiddaten!$C$5:$C$304,Schneiddaten!$A$5:$A$304,$C$8,Schneiddaten!$B$5:$B$304,$E13,Schneiddaten!$C$5:$C$304,">="&M13)=0,"",SUMIFS(Schneiddaten!$D$5:$D$304,Schneiddaten!$A$5:$A$304,$C$8,Schneiddaten!$B$5:$B$304,$E13,Schneiddaten!$C$5:$C$304,_xlfn.MINIFS(Schneiddaten!$C$5:$C$304,Schneiddaten!$A$5:$A$304,$C$8,Schneiddaten!$B$5:$B$304,$E13,Schneiddaten!$C$5:$C$304,">="&M13)))) -> 6000 | W13: =IF(AND($D13="",$E13="",$F13="",$G13=""),"",IF(ISNA(MATCH($D13,lst_Profil,0)),"FEHLER: Profil unbekannt",IF(ISNA(MATCH($E13,lst_Werkstoff,0)),"FEHLER: Werkstoff unbekannt",IF(NOT(ISNUMBER(L13)),"FEHLER: Querschnitt fehlt (Profil)",IF(OR($F13="",$F13<=0),"FEHLER: Teilelänge fehlt",IF(OR($G13="",$G13<1),"FEHLER: Stückzahl fehlt",IF(NOT(ISNUMBER($H$4)),"FEHLER: Maschine fehlt/unbekannt",IF(Q13>$H$7,"FEHLER: Stange länger als Maschine zulässt",IF($F13+$H$6>T13,"FEHLER: Teil länger als Nutzlänge",IF(U13="nein","WARNUNG: kein gültiger Materialpreis",IF($H13="","HINWEIS: Schneidweg fehlt",IF(V13="","HINWEIS: keine Schneiddaten",IF(AND($AF13<>"",$AG13=""),"HINWEIS: Gewinde-Vorschlag prüfen","OK"))))))))))))) -> OK | X13: =IF(OR(O13="",$G13=""),"",O13*$G13) -> 59.779482
A14: 20 | B14: 4711-002 | C14: Querstrebe | D14: RR 42,4x2,0 | E14: S235-10219 | F14: 860 | G14: 40 | H14: 302 | I14: 2 | K14: =IF($D14="","",IFERROR(INDEX(Profile!$B$5:$B$304,MATCH($D14,lst_Profil,0)),"")) -> Rundrohr | L14: =IF($D14="","",IFERROR(INDEX(Profile!$K$5:$K$304,MATCH($D14,lst_Profil,0))+0,"")) -> 253.84069 | M14: =IF($D14="","",IFERROR(INDEX(Profile!$E$5:$E$304,MATCH($D14,lst_Profil,0))+0,"")) -> 2 | N14: =IF(OR(L14="",$E14=""),"",IFERROR(L14*INDEX(Werkstoffe!$E$5:$E$304,MATCH($E14,lst_Werkstoff,0))/1000,"")) -> 1.9926494 | O14: =IF(OR(N14="",$F14=""),"",N14*$F14/1000) -> 1.7136785 | P14: =IF(OR($F14="",$G14=""),"",$F14*$G14) -> 34400 | Q14: =IF($D14="","",IF($J14<>"",$J14,$C$9)) -> 6000 | R14: =IF($D14="","",IFERROR(IF(INDEX(Profile!$G$5:$G$304,MATCH($D14,lst_Profil,0))<>"",INDEX(Profile!$G$5:$G$304,MATCH($D14,lst_Profil,0)),$H$4),$H$4)) -> 20 | S14: =IF($D14="","",IFERROR(IF(INDEX(Profile!$H$5:$H$304,MATCH($D14,lst_Profil,0))<>"",INDEX(Profile!$H$5:$H$304,MATCH($D14,lst_Profil,0)),$H$5),$H$5)) -> 80 | T14: =IF(OR(Q14="",NOT(ISNUMBER(R14)),NOT(ISNUMBER(S14))),"",Q14-R14-S14) -> 5900 | U14: =IF(OR($D14="",$E14=""),"",IF(COUNTIFS(Preise!$A$5:$A$304,$D14,Preise!$B$5:$B$304,$E14,Preise!$I$5:$I$304,"OK")>0,"ja","nein")) -> ja | V14: =IF(OR(M14="",$E14="",$C$8=""),"",IF(_xlfn.MINIFS(Schneiddaten!$C$5:$C$304,Schneiddaten!$A$5:$A$304,$C$8,Schneiddaten!$B$5:$B$304,$E14,Schneiddaten!$C$5:$C$304,">="&M14)=0,"",SUMIFS(Schneiddaten!$D$5:$D$304,Schneiddaten!$A$5:$A$304,$C$8,Schneiddaten!$B$5:$B$304,$E14,Schneiddaten!$C$5:$C$304,_xlfn.MINIFS(Schneiddaten!$C$5:$C$304,Schneiddaten!$A$5:$A$304,$C$8,Schneiddaten!$B$5:$B$304,$E14,Schneiddaten!$C$5:$C$304,">="&M14)))) -> 6000 | W14: =IF(AND($D14="",$E14="",$F14="",$G14=""),"",IF(ISNA(MATCH($D14,lst_Profil,0)),"FEHLER: Profil unbekannt",IF(ISNA(MATCH($E14,lst_Werkstoff,0)),"FEHLER: Werkstoff unbekannt",IF(NOT(ISNUMBER(L14)),"FEHLER: Querschnitt fehlt (Profil)",IF(OR($F14="",$F14<=0),"FEHLER: Teilelänge fehlt",IF(OR($G14="",$G14<1),"FEHLER: Stückzahl fehlt",IF(NOT(ISNUMBER($H$4)),"FEHLER: Maschine fehlt/unbekannt",IF(Q14>$H$7,"FEHLER: Stange länger als Maschine zulässt",IF($F14+$H$6>T14,"FEHLER: Teil länger als Nutzlänge",IF(U14="nein","WARNUNG: kein gültiger Materialpreis",IF($H14="","HINWEIS: Schneidweg fehlt",IF(V14="","HINWEIS: keine Schneiddaten",IF(AND($AF14<>"",$AG14=""),"HINWEIS: Gewinde-Vorschlag prüfen","OK"))))))))))))) -> OK | X14: =IF(OR(O14="",$G14=""),"",O14*$G14) -> 68.547139
A15: 30 | B15: 4711-003 | C15: Rahmen oben | D15: QR 40x40x3 | E15: S235-10219 | F15: 2150 | G15: 12 | H15: 520 | I15: 3 | K15: =IF($D15="","",IFERROR(INDEX(Profile!$B$5:$B$304,MATCH($D15,lst_Profil,0)),"")) -> Quadratrohr | L15: =IF($D15="","",IFERROR(INDEX(Profile!$K$5:$K$304,MATCH($D15,lst_Profil,0))+0,"")) -> 444 | M15: =IF($D15="","",IFERROR(INDEX(Profile!$E$5:$E$304,MATCH($D15,lst_Profil,0))+0,"")) -> 3 | N15: =IF(OR(L15="",$E15=""),"",IFERROR(L15*INDEX(Werkstoffe!$E$5:$E$304,MATCH($E15,lst_Werkstoff,0))/1000,"")) -> 3.4854 | O15: =IF(OR(N15="",$F15=""),"",N15*$F15/1000) -> 7.49361 | P15: =IF(OR($F15="",$G15=""),"",$F15*$G15) -> 25800 | Q15: =IF($D15="","",IF($J15<>"",$J15,$C$9)) -> 6000 | R15: =IF($D15="","",IFERROR(IF(INDEX(Profile!$G$5:$G$304,MATCH($D15,lst_Profil,0))<>"",INDEX(Profile!$G$5:$G$304,MATCH($D15,lst_Profil,0)),$H$4),$H$4)) -> 20 | S15: =IF($D15="","",IFERROR(IF(INDEX(Profile!$H$5:$H$304,MATCH($D15,lst_Profil,0))<>"",INDEX(Profile!$H$5:$H$304,MATCH($D15,lst_Profil,0)),$H$5),$H$5)) -> 80 | T15: =IF(OR(Q15="",NOT(ISNUMBER(R15)),NOT(ISNUMBER(S15))),"",Q15-R15-S15) -> 5900 | U15: =IF(OR($D15="",$E15=""),"",IF(COUNTIFS(Preise!$A$5:$A$304,$D15,Preise!$B$5:$B$304,$E15,Preise!$I$5:$I$304,"OK")>0,"ja","nein")) -> ja | V15: =IF(OR(M15="",$E15="",$C$8=""),"",IF(_xlfn.MINIFS(Schneiddaten!$C$5:$C$304,Schneiddaten!$A$5:$A$304,$C$8,Schneiddaten!$B$5:$B$304,$E15,Schneiddaten!$C$5:$C$304,">="&M15)=0,"",SUMIFS(Schneiddaten!$D$5:$D$304,Schneiddaten!$A$5:$A$304,$C$8,Schneiddaten!$B$5:$B$304,$E15,Schneiddaten!$C$5:$C$304,_xlfn.MINIFS(Schneiddaten!$C$5:$C$304,Schneiddaten!$A$5:$A$304,$C$8,Schneiddaten!$B$5:$B$304,$E15,Schneiddaten!$C$5:$C$304,">="&M15)))) -> 4500 | W15: =IF(AND($D15="",$E15="",$F15="",$G15=""),"",IF(ISNA(MATCH($D15,lst_Profil,0)),"FEHLER: Profil unbekannt",IF(ISNA(MATCH($E15,lst_Werkstoff,0)),"FEHLER: Werkstoff unbekannt",IF(NOT(ISNUMBER(L15)),"FEHLER: Querschnitt fehlt (Profil)",IF(OR($F15="",$F15<=0),"FEHLER: Teilelänge fehlt",IF(OR($G15="",$G15<1),"FEHLER: Stückzahl fehlt",IF(NOT(ISNUMBER($H$4)),"FEHLER: Maschine fehlt/unbekannt",IF(Q15>$H$7,"FEHLER: Stange länger als Maschine zulässt",IF($F15+$H$6>T15,"FEHLER: Teil länger als Nutzlänge",IF(U15="nein","WARNUNG: kein gültiger Materialpreis",IF($H15="","HINWEIS: Schneidweg fehlt",IF(V15="","HINWEIS: keine Schneiddaten",IF(AND($AF15<>"",$AG15=""),"HINWEIS: Gewinde-Vorschlag prüfen","OK"))))))))))))) -> OK | X15: =IF(OR(O15="",$G15=""),"",O15*$G15) -> 89.92332
A16: 40 | B16: 4711-004 | C16: Stütze | D16: RE 60x40x3 | E16: S355-10219 | F16: 1795.5 | G16: 16 | H16: 618.2 | I16: 4 | K16: =IF($D16="","",IFERROR(INDEX(Profile!$B$5:$B$304,MATCH($D16,lst_Profil,0)),"")) -> Rechteckrohr | L16: =IF($D16="","",IFERROR(INDEX(Profile!$K$5:$K$304,MATCH($D16,lst_Profil,0))+0,"")) -> 564 | M16: =IF($D16="","",IFERROR(INDEX(Profile!$E$5:$E$304,MATCH($D16,lst_Profil,0))+0,"")) -> 3 | N16: =IF(OR(L16="",$E16=""),"",IFERROR(L16*INDEX(Werkstoffe!$E$5:$E$304,MATCH($E16,lst_Werkstoff,0))/1000,"")) -> 4.4274 | O16: =IF(OR(N16="",$F16=""),"",N16*$F16/1000) -> 7.9493967 | P16: =IF(OR($F16="",$G16=""),"",$F16*$G16) -> 28728 | Q16: =IF($D16="","",IF($J16<>"",$J16,$C$9)) -> 6000 | R16: =IF($D16="","",IFERROR(IF(INDEX(Profile!$G$5:$G$304,MATCH($D16,lst_Profil,0))<>"",INDEX(Profile!$G$5:$G$304,MATCH($D16,lst_Profil,0)),$H$4),$H$4)) -> 20 | S16: =IF($D16="","",IFERROR(IF(INDEX(Profile!$H$5:$H$304,MATCH($D16,lst_Profil,0))<>"",INDEX(Profile!$H$5:$H$304,MATCH($D16,lst_Profil,0)),$H$5),$H$5)) -> 80 | T16: =IF(OR(Q16="",NOT(ISNUMBER(R16)),NOT(ISNUMBER(S16))),"",Q16-R16-S16) -> 5900 | U16: =IF(OR($D16="",$E16=""),"",IF(COUNTIFS(Preise!$A$5:$A$304,$D16,Preise!$B$5:$B$304,$E16,Preise!$I$5:$I$304,"OK")>0,"ja","nein")) -> ja | V16: =IF(OR(M16="",$E16="",$C$8=""),"",IF(_xlfn.MINIFS(Schneiddaten!$C$5:$C$304,Schneiddaten!$A$5:$A$304,$C$8,Schneiddaten!$B$5:$B$304,$E16,Schneiddaten!$C$5:$C$304,">="&M16)=0,"",SUMIFS(Schneiddaten!$D$5:$D$304,Schneiddaten!$A$5:$A$304,$C$8,Schneiddaten!$B$5:$B$304,$E16,Schneiddaten!$C$5:$C$304,_xlfn.MINIFS(Schneiddaten!$C$5:$C$304,Schneiddaten!$A$5:$A$304,$C$8,Schneiddaten!$B$5:$B$304,$E16,Schneiddaten!$C$5:$C$304,">="&M16)))) -> 4300 | W16: =IF(AND($D16="",$E16="",$F16="",$G16=""),"",IF(ISNA(MATCH($D16,lst_Profil,0)),"FEHLER: Profil unbekannt",IF(ISNA(MATCH($E16,lst_Werkstoff,0)),"FEHLER: Werkstoff unbekannt",IF(NOT(ISNUMBER(L16)),"FEHLER: Querschnitt fehlt (Profil)",IF(OR($F16="",$F16<=0),"FEHLER: Teilelänge fehlt",IF(OR($G16="",$G16<1),"FEHLER: Stückzahl fehlt",IF(NOT(ISNUMBER($H$4)),"FEHLER: Maschine fehlt/unbekannt",IF(Q16>$H$7,"FEHLER: Stange länger als Maschine zulässt",IF($F16+$H$6>T16,"FEHLER: Teil länger als Nutzlänge",IF(U16="nein","WARNUNG: kein gültiger Materialpreis",IF($H16="","HINWEIS: Schneidweg fehlt",IF(V16="","HINWEIS: keine Schneiddaten",IF(AND($AF16<>"",$AG16=""),"HINWEIS: Gewinde-Vorschlag prüfen","OK"))))))))))))) -> OK | X16: =IF(OR(O16="",$G16=""),"",O16*$G16) -> 127.19035
A17: 50 | B17: 4711-005 | C17: Anschlag | D17: RR 48,3x2,6 | E17: S235-10219 | F17: 345 | G17: 60 | H17: 255 | I17: 2 | K17: =IF($D17="","",IFERROR(INDEX(Profile!$B$5:$B$304,MATCH($D17,lst_Profil,0)),"")) -> Rundrohr | L17: =IF($D17="","",IFERROR(INDEX(Profile!$K$5:$K$304,MATCH($D17,lst_Profil,0))+0,"")) -> 373.28404 | M17: =IF($D17="","",IFERROR(INDEX(Profile!$E$5:$E$304,MATCH($D17,lst_Profil,0))+0,"")) -> 2.6 | N17: =IF(OR(L17="",$E17=""),"",IFERROR(L17*INDEX(Werkstoffe!$E$5:$E$304,MATCH($E17,lst_Werkstoff,0))/1000,"")) -> 2.9302797 | O17: =IF(OR(N17="",$F17=""),"",N17*$F17/1000) -> 1.0109465 | P17: =IF(OR($F17="",$G17=""),"",$F17*$G17) -> 20700 | Q17: =IF($D17="","",IF($J17<>"",$J17,$C$9)) -> 6000 | R17: =IF($D17="","",IFERROR(IF(INDEX(Profile!$G$5:$G$304,MATCH($D17,lst_Profil,0))<>"",INDEX(Profile!$G$5:$G$304,MATCH($D17,lst_Profil,0)),$H$4),$H$4)) -> 20 | S17: =IF($D17="","",IFERROR(IF(INDEX(Profile!$H$5:$H$304,MATCH($D17,lst_Profil,0))<>"",INDEX(Profile!$H$5:$H$304,MATCH($D17,lst_Profil,0)),$H$5),$H$5)) -> 80 | T17: =IF(OR(Q17="",NOT(ISNUMBER(R17)),NOT(ISNUMBER(S17))),"",Q17-R17-S17) -> 5900 | U17: =IF(OR($D17="",$E17=""),"",IF(COUNTIFS(Preise!$A$5:$A$304,$D17,Preise!$B$5:$B$304,$E17,Preise!$I$5:$I$304,"OK")>0,"ja","nein")) -> ja | V17: =IF(OR(M17="",$E17="",$C$8=""),"",IF(_xlfn.MINIFS(Schneiddaten!$C$5:$C$304,Schneiddaten!$A$5:$A$304,$C$8,Schneiddaten!$B$5:$B$304,$E17,Schneiddaten!$C$5:$C$304,">="&M17)=0,"",SUMIFS(Schneiddaten!$D$5:$D$304,Schneiddaten!$A$5:$A$304,$C$8,Schneiddaten!$B$5:$B$304,$E17,Schneiddaten!$C$5:$C$304,_xlfn.MINIFS(Schneiddaten!$C$5:$C$304,Schneiddaten!$A$5:$A$304,$C$8,Schneiddaten!$B$5:$B$304,$E17,Schneiddaten!$C$5:$C$304,">="&M17)))) -> 4500 | W17: =IF(AND($D17="",$E17="",$F17="",$G17=""),"",IF(ISNA(MATCH($D17,lst_Profil,0)),"FEHLER: Profil unbekannt",IF(ISNA(MATCH($E17,lst_Werkstoff,0)),"FEHLER: Werkstoff unbekannt",IF(NOT(ISNUMBER(L17)),"FEHLER: Querschnitt fehlt (Profil)",IF(OR($F17="",$F17<=0),"FEHLER: Teilelänge fehlt",IF(OR($G17="",$G17<1),"FEHLER: Stückzahl fehlt",IF(NOT(ISNUMBER($H$4)),"FEHLER: Maschine fehlt/unbekannt",IF(Q17>$H$7,"FEHLER: Stange länger als Maschine zulässt",IF($F17+$H$6>T17,"FEHLER: Teil länger als Nutzlänge",IF(U17="nein","WARNUNG: kein gültiger Materialpreis",IF($H17="","HINWEIS: Schneidweg fehlt",IF(V17="","HINWEIS: keine Schneiddaten",IF(AND($AF17<>"",$AG17=""),"HINWEIS: Gewinde-Vorschlag prüfen","OK"))))))))))))) -> OK | X17: =IF(OR(O17="",$G17=""),"",O17*$G17) -> 60.65679
K18: =IF($D18="","",IFERROR(INDEX(Profile!$B$5:$B$304,MATCH($D18,lst_Profil,0)),"")) | L18: =IF($D18="","",IFERROR(INDEX(Profile!$K$5:$K$304,MATCH($D18,lst_Profil,0))+0,"")) | M18: =IF($D18="","",IFERROR(INDEX(Profile!$E$5:$E$304,MATCH($D18,lst_Profil,0))+0,"")) | N18: =IF(OR(L18="",$E18=""),"",IFERROR(L18*INDEX(Werkstoffe!$E$5:$E$304,MATCH($E18,lst_Werkstoff,0))/1000,"")) | O18: =IF(OR(N18="",$F18=""),"",N18*$F18/1000) | P18: =IF(OR($F18="",$G18=""),"",$F18*$G18) | Q18: =IF($D18="","",IF($J18<>"",$J18,$C$9)) | R18: =IF($D18="","",IFERROR(IF(INDEX(Profile!$G$5:$G$304,MATCH($D18,lst_Profil,0))<>"",INDEX(Profile!$G$5:$G$304,MATCH($D18,lst_Profil,0)),$H$4),$H$4)) | S18: =IF($D18="","",IFERROR(IF(INDEX(Profile!$H$5:$H$304,MATCH($D18,lst_Profil,0))<>"",INDEX(Profile!$H$5:$H$304,MATCH($D18,lst_Profil,0)),$H$5),$H$5)) | T18: =IF(OR(Q18="",NOT(ISNUMBER(R18)),NOT(ISNUMBER(S18))),"",Q18-R18-S18) | U18: =IF(OR($D18="",$E18=""),"",IF(COUNTIFS(Preise!$A$5:$A$304,$D18,Preise!$B$5:$B$304,$E18,Preise!$I$5:$I$304,"OK")>0,"ja","nein")) | V18: =IF(OR(M18="",$E18="",$C$8=""),"",IF(_xlfn.MINIFS(Schneiddaten!$C$5:$C$304,Schneiddaten!$A$5:$A$304,$C$8,Schneiddaten!$B$5:$B$304,$E18,Schneiddaten!$C$5:$C$304,">="&M18)=0,"",SUMIFS(Schneiddaten!$D$5:$D$304,Schneiddaten!$A$5:$A$304,$C$8,Schneiddaten!$B$5:$B$304,$E18,Schneiddaten!$C$5:$C$304,_xlfn.MINIFS(Schneiddaten!$C$5:$C$304,Schneiddaten!$A$5:$A$304,$C$8,Schneiddaten!$B$5:$B$304,$E18,Schneiddaten!$C$5:$C$304,">="&M18)))) | W18: =IF(AND($D18="",$E18="",$F18="",$G18=""),"",IF(ISNA(MATCH($D18,lst_Profil,0)),"FEHLER: Profil unbekannt",IF(ISNA(MATCH($E18,lst_Werkstoff,0)),"FEHLER: Werkstoff unbekannt",IF(NOT(ISNUMBER(L18)),"FEHLER: Querschnitt fehlt (Profil)",IF(OR($F18="",$F18<=0),"FEHLER: Teilelänge fehlt",IF(OR($G18="",$G18<1),"FEHLER: Stückzahl fehlt",IF(NOT(ISNUMBER($H$4)),"FEHLER: Maschine fehlt/unbekannt",IF(Q18>$H$7,"FEHLER: Stange länger als Maschine zulässt",IF($F18+$H$6>T18,"FEHLER: Teil länger als Nutzlänge",IF(U18="nein","WARNUNG: kein gültiger Materialpreis",IF($H18="","HINWEIS: Schneidweg fehlt",IF(V18="","HINWEIS: keine Schneiddaten",IF(AND($AF18<>"",$AG18=""),"HINWEIS: Gewinde-Vorschlag prüfen","OK"))))))))))))) | X18: =IF(OR(O18="",$G18=""),"",O18*$G18)
K19: =IF($D19="","",IFERROR(INDEX(Profile!$B$5:$B$304,MATCH($D19,lst_Profil,0)),"")) | L19: =IF($D19="","",IFERROR(INDEX(Profile!$K$5:$K$304,MATCH($D19,lst_Profil,0))+0,"")) | M19: =IF($D19="","",IFERROR(INDEX(Profile!$E$5:$E$304,MATCH($D19,lst_Profil,0))+0,"")) | N19: =IF(OR(L19="",$E19=""),"",IFERROR(L19*INDEX(Werkstoffe!$E$5:$E$304,MATCH($E19,lst_Werkstoff,0))/1000,"")) | O19: =IF(OR(N19="",$F19=""),"",N19*$F19/1000) | P19: =IF(OR($F19="",$G19=""),"",$F19*$G19) | Q19: =IF($D19="","",IF($J19<>"",$J19,$C$9)) | R19: =IF($D19="","",IFERROR(IF(INDEX(Profile!$G$5:$G$304,MATCH($D19,lst_Profil,0))<>"",INDEX(Profile!$G$5:$G$304,MATCH($D19,lst_Profil,0)),$H$4),$H$4)) | S19: =IF($D19="","",IFERROR(IF(INDEX(Profile!$H$5:$H$304,MATCH($D19,lst_Profil,0))<>"",INDEX(Profile!$H$5:$H$304,MATCH($D19,lst_Profil,0)),$H$5),$H$5)) | T19: =IF(OR(Q19="",NOT(ISNUMBER(R19)),NOT(ISNUMBER(S19))),"",Q19-R19-S19) | U19: =IF(OR($D19="",$E19=""),"",IF(COUNTIFS(Preise!$A$5:$A$304,$D19,Preise!$B$5:$B$304,$E19,Preise!$I$5:$I$304,"OK")>0,"ja","nein")) | V19: =IF(OR(M19="",$E19="",$C$8=""),"",IF(_xlfn.MINIFS(Schneiddaten!$C$5:$C$304,Schneiddaten!$A$5:$A$304,$C$8,Schneiddaten!$B$5:$B$304,$E19,Schneiddaten!$C$5:$C$304,">="&M19)=0,"",SUMIFS(Schneiddaten!$D$5:$D$304,Schneiddaten!$A$5:$A$304,$C$8,Schneiddaten!$B$5:$B$304,$E19,Schneiddaten!$C$5:$C$304,_xlfn.MINIFS(Schneiddaten!$C$5:$C$304,Schneiddaten!$A$5:$A$304,$C$8,Schneiddaten!$B$5:$B$304,$E19,Schneiddaten!$C$5:$C$304,">="&M19)))) | W19: =IF(AND($D19="",$E19="",$F19="",$G19=""),"",IF(ISNA(MATCH($D19,lst_Profil,0)),"FEHLER: Profil unbekannt",IF(ISNA(MATCH($E19,lst_Werkstoff,0)),"FEHLER: Werkstoff unbekannt",IF(NOT(ISNUMBER(L19)),"FEHLER: Querschnitt fehlt (Profil)",IF(OR($F19="",$F19<=0),"FEHLER: Teilelänge fehlt",IF(OR($G19="",$G19<1),"FEHLER: Stückzahl fehlt",IF(NOT(ISNUMBER($H$4)),"FEHLER: Maschine fehlt/unbekannt",IF(Q19>$H$7,"FEHLER: Stange länger als Maschine zulässt",IF($F19+$H$6>T19,"FEHLER: Teil länger als Nutzlänge",IF(U19="nein","WARNUNG: kein gültiger Materialpreis",IF($H19="","HINWEIS: Schneidweg fehlt",IF(V19="","HINWEIS: keine Schneiddaten",IF(AND($AF19<>"",$AG19=""),"HINWEIS: Gewinde-Vorschlag prüfen","OK"))))))))))))) | X19: =IF(OR(O19="",$G19=""),"",O19*$G19)
K20: =IF($D20="","",IFERROR(INDEX(Profile!$B$5:$B$304,MATCH($D20,lst_Profil,0)),"")) | L20: =IF($D20="","",IFERROR(INDEX(Profile!$K$5:$K$304,MATCH($D20,lst_Profil,0))+0,"")) | M20: =IF($D20="","",IFERROR(INDEX(Profile!$E$5:$E$304,MATCH($D20,lst_Profil,0))+0,"")) | N20: =IF(OR(L20="",$E20=""),"",IFERROR(L20*INDEX(Werkstoffe!$E$5:$E$304,MATCH($E20,lst_Werkstoff,0))/1000,"")) | O20: =IF(OR(N20="",$F20=""),"",N20*$F20/1000) | P20: =IF(OR($F20="",$G20=""),"",$F20*$G20) | Q20: =IF($D20="","",IF($J20<>"",$J20,$C$9)) | R20: =IF($D20="","",IFERROR(IF(INDEX(Profile!$G$5:$G$304,MATCH($D20,lst_Profil,0))<>"",INDEX(Profile!$G$5:$G$304,MATCH($D20,lst_Profil,0)),$H$4),$H$4)) | S20: =IF($D20="","",IFERROR(IF(INDEX(Profile!$H$5:$H$304,MATCH($D20,lst_Profil,0))<>"",INDEX(Profile!$H$5:$H$304,MATCH($D20,lst_Profil,0)),$H$5),$H$5)) | T20: =IF(OR(Q20="",NOT(ISNUMBER(R20)),NOT(ISNUMBER(S20))),"",Q20-R20-S20) | U20: =IF(OR($D20="",$E20=""),"",IF(COUNTIFS(Preise!$A$5:$A$304,$D20,Preise!$B$5:$B$304,$E20,Preise!$I$5:$I$304,"OK")>0,"ja","nein")) | V20: =IF(OR(M20="",$E20="",$C$8=""),"",IF(_xlfn.MINIFS(Schneiddaten!$C$5:$C$304,Schneiddaten!$A$5:$A$304,$C$8,Schneiddaten!$B$5:$B$304,$E20,Schneiddaten!$C$5:$C$304,">="&M20)=0,"",SUMIFS(Schneiddaten!$D$5:$D$304,Schneiddaten!$A$5:$A$304,$C$8,Schneiddaten!$B$5:$B$304,$E20,Schneiddaten!$C$5:$C$304,_xlfn.MINIFS(Schneiddaten!$C$5:$C$304,Schneiddaten!$A$5:$A$304,$C$8,Schneiddaten!$B$5:$B$304,$E20,Schneiddaten!$C$5:$C$304,">="&M20)))) | W20: =IF(AND($D20="",$E20="",$F20="",$G20=""),"",IF(ISNA(MATCH($D20,lst_Profil,0)),"FEHLER: Profil unbekannt",IF(ISNA(MATCH($E20,lst_Werkstoff,0)),"FEHLER: Werkstoff unbekannt",IF(NOT(ISNUMBER(L20)),"FEHLER: Querschnitt fehlt (Profil)",IF(OR($F20="",$F20<=0),"FEHLER: Teilelänge fehlt",IF(OR($G20="",$G20<1),"FEHLER: Stückzahl fehlt",IF(NOT(ISNUMBER($H$4)),"FEHLER: Maschine fehlt/unbekannt",IF(Q20>$H$7,"FEHLER: Stange länger als Maschine zulässt",IF($F20+$H$6>T20,"FEHLER: Teil länger als Nutzlänge",IF(U20="nein","WARNUNG: kein gültiger Materialpreis",IF($H20="","HINWEIS: Schneidweg fehlt",IF(V20="","HINWEIS: keine Schneiddaten",IF(AND($AF20<>"",$AG20=""),"HINWEIS: Gewinde-Vorschlag prüfen","OK"))))))))))))) | X20: =IF(OR(O20="",$G20=""),"",O20*$G20)
K21: =IF($D21="","",IFERROR(INDEX(Profile!$B$5:$B$304,MATCH($D21,lst_Profil,0)),"")) | L21: =IF($D21="","",IFERROR(INDEX(Profile!$K$5:$K$304,MATCH($D21,lst_Profil,0))+0,"")) | M21: =IF($D21="","",IFERROR(INDEX(Profile!$E$5:$E$304,MATCH($D21,lst_Profil,0))+0,"")) | N21: =IF(OR(L21="",$E21=""),"",IFERROR(L21*INDEX(Werkstoffe!$E$5:$E$304,MATCH($E21,lst_Werkstoff,0))/1000,"")) | O21: =IF(OR(N21="",$F21=""),"",N21*$F21/1000) | P21: =IF(OR($F21="",$G21=""),"",$F21*$G21) | Q21: =IF($D21="","",IF($J21<>"",$J21,$C$9)) | R21: =IF($D21="","",IFERROR(IF(INDEX(Profile!$G$5:$G$304,MATCH($D21,lst_Profil,0))<>"",INDEX(Profile!$G$5:$G$304,MATCH($D21,lst_Profil,0)),$H$4),$H$4)) | S21: =IF($D21="","",IFERROR(IF(INDEX(Profile!$H$5:$H$304,MATCH($D21,lst_Profil,0))<>"",INDEX(Profile!$H$5:$H$304,MATCH($D21,lst_Profil,0)),$H$5),$H$5)) | T21: =IF(OR(Q21="",NOT(ISNUMBER(R21)),NOT(ISNUMBER(S21))),"",Q21-R21-S21) | U21: =IF(OR($D21="",$E21=""),"",IF(COUNTIFS(Preise!$A$5:$A$304,$D21,Preise!$B$5:$B$304,$E21,Preise!$I$5:$I$304,"OK")>0,"ja","nein")) | V21: =IF(OR(M21="",$E21="",$C$8=""),"",IF(_xlfn.MINIFS(Schneiddaten!$C$5:$C$304,Schneiddaten!$A$5:$A$304,$C$8,Schneiddaten!$B$5:$B$304,$E21,Schneiddaten!$C$5:$C$304,">="&M21)=0,"",SUMIFS(Schneiddaten!$D$5:$D$304,Schneiddaten!$A$5:$A$304,$C$8,Schneiddaten!$B$5:$B$304,$E21,Schneiddaten!$C$5:$C$304,_xlfn.MINIFS(Schneiddaten!$C$5:$C$304,Schneiddaten!$A$5:$A$304,$C$8,Schneiddaten!$B$5:$B$304,$E21,Schneiddaten!$C$5:$C$304,">="&M21)))) | W21: =IF(AND($D21="",$E21="",$F21="",$G21=""),"",IF(ISNA(MATCH($D21,lst_Profil,0)),"FEHLER: Profil unbekannt",IF(ISNA(MATCH($E21,lst_Werkstoff,0)),"FEHLER: Werkstoff unbekannt",IF(NOT(ISNUMBER(L21)),"FEHLER: Querschnitt fehlt (Profil)",IF(OR($F21="",$F21<=0),"FEHLER: Teilelänge fehlt",IF(OR($G21="",$G21<1),"FEHLER: Stückzahl fehlt",IF(NOT(ISNUMBER($H$4)),"FEHLER: Maschine fehlt/unbekannt",IF(Q21>$H$7,"FEHLER: Stange länger als Maschine zulässt",IF($F21+$H$6>T21,"FEHLER: Teil länger als Nutzlänge",IF(U21="nein","WARNUNG: kein gültiger Materialpreis",IF($H21="","HINWEIS: Schneidweg fehlt",IF(V21="","HINWEIS: keine Schneiddaten",IF(AND($AF21<>"",$AG21=""),"HINWEIS: Gewinde-Vorschlag prüfen","OK"))))))))))))) | X21: =IF(OR(O21="",$G21=""),"",O21*$G21)
K22: =IF($D22="","",IFERROR(INDEX(Profile!$B$5:$B$304,MATCH($D22,lst_Profil,0)),"")) | L22: =IF($D22="","",IFERROR(INDEX(Profile!$K$5:$K$304,MATCH($D22,lst_Profil,0))+0,"")) | M22: =IF($D22="","",IFERROR(INDEX(Profile!$E$5:$E$304,MATCH($D22,lst_Profil,0))+0,"")) | N22: =IF(OR(L22="",$E22=""),"",IFERROR(L22*INDEX(Werkstoffe!$E$5:$E$304,MATCH($E22,lst_Werkstoff,0))/1000,"")) | O22: =IF(OR(N22="",$F22=""),"",N22*$F22/1000) | P22: =IF(OR($F22="",$G22=""),"",$F22*$G22) | Q22: =IF($D22="","",IF($J22<>"",$J22,$C$9)) | R22: =IF($D22="","",IFERROR(IF(INDEX(Profile!$G$5:$G$304,MATCH($D22,lst_Profil,0))<>"",INDEX(Profile!$G$5:$G$304,MATCH($D22,lst_Profil,0)),$H$4),$H$4)) | S22: =IF($D22="","",IFERROR(IF(INDEX(Profile!$H$5:$H$304,MATCH($D22,lst_Profil,0))<>"",INDEX(Profile!$H$5:$H$304,MATCH($D22,lst_Profil,0)),$H$5),$H$5)) | T22: =IF(OR(Q22="",NOT(ISNUMBER(R22)),NOT(ISNUMBER(S22))),"",Q22-R22-S22) | U22: =IF(OR($D22="",$E22=""),"",IF(COUNTIFS(Preise!$A$5:$A$304,$D22,Preise!$B$5:$B$304,$E22,Preise!$I$5:$I$304,"OK")>0,"ja","nein")) | V22: =IF(OR(M22="",$E22="",$C$8=""),"",IF(_xlfn.MINIFS(Schneiddaten!$C$5:$C$304,Schneiddaten!$A$5:$A$304,$C$8,Schneiddaten!$B$5:$B$304,$E22,Schneiddaten!$C$5:$C$304,">="&M22)=0,"",SUMIFS(Schneiddaten!$D$5:$D$304,Schneiddaten!$A$5:$A$304,$C$8,Schneiddaten!$B$5:$B$304,$E22,Schneiddaten!$C$5:$C$304,_xlfn.MINIFS(Schneiddaten!$C$5:$C$304,Schneiddaten!$A$5:$A$304,$C$8,Schneiddaten!$B$5:$B$304,$E22,Schneiddaten!$C$5:$C$304,">="&M22)))) | W22: =IF(AND($D22="",$E22="",$F22="",$G22=""),"",IF(ISNA(MATCH($D22,lst_Profil,0)),"FEHLER: Profil unbekannt",IF(ISNA(MATCH($E22,lst_Werkstoff,0)),"FEHLER: Werkstoff unbekannt",IF(NOT(ISNUMBER(L22)),"FEHLER: Querschnitt fehlt (Profil)",IF(OR($F22="",$F22<=0),"FEHLER: Teilelänge fehlt",IF(OR($G22="",$G22<1),"FEHLER: Stückzahl fehlt",IF(NOT(ISNUMBER($H$4)),"FEHLER: Maschine fehlt/unbekannt",IF(Q22>$H$7,"FEHLER: Stange länger als Maschine zulässt",IF($F22+$H$6>T22,"FEHLER: Teil länger als Nutzlänge",IF(U22="nein","WARNUNG: kein gültiger Materialpreis",IF($H22="","HINWEIS: Schneidweg fehlt",IF(V22="","HINWEIS: keine Schneiddaten",IF(AND($AF22<>"",$AG22=""),"HINWEIS: Gewinde-Vorschlag prüfen","OK"))))))))))))) | X22: =IF(OR(O22="",$G22=""),"",O22*$G22)
K23: =IF($D23="","",IFERROR(INDEX(Profile!$B$5:$B$304,MATCH($D23,lst_Profil,0)),"")) | L23: =IF($D23="","",IFERROR(INDEX(Profile!$K$5:$K$304,MATCH($D23,lst_Profil,0))+0,"")) | M23: =IF($D23="","",IFERROR(INDEX(Profile!$E$5:$E$304,MATCH($D23,lst_Profil,0))+0,"")) | N23: =IF(OR(L23="",$E23=""),"",IFERROR(L23*INDEX(Werkstoffe!$E$5:$E$304,MATCH($E23,lst_Werkstoff,0))/1000,"")) | O23: =IF(OR(N23="",$F23=""),"",N23*$F23/1000) | P23: =IF(OR($F23="",$G23=""),"",$F23*$G23) | Q23: =IF($D23="","",IF($J23<>"",$J23,$C$9)) | R23: =IF($D23="","",IFERROR(IF(INDEX(Profile!$G$5:$G$304,MATCH($D23,lst_Profil,0))<>"",INDEX(Profile!$G$5:$G$304,MATCH($D23,lst_Profil,0)),$H$4),$H$4)) | S23: =IF($D23="","",IFERROR(IF(INDEX(Profile!$H$5:$H$304,MATCH($D23,lst_Profil,0))<>"",INDEX(Profile!$H$5:$H$304,MATCH($D23,lst_Profil,0)),$H$5),$H$5)) | T23: =IF(OR(Q23="",NOT(ISNUMBER(R23)),NOT(ISNUMBER(S23))),"",Q23-R23-S23) | U23: =IF(OR($D23="",$E23=""),"",IF(COUNTIFS(Preise!$A$5:$A$304,$D23,Preise!$B$5:$B$304,$E23,Preise!$I$5:$I$304,"OK")>0,"ja","nein")) | V23: =IF(OR(M23="",$E23="",$C$8=""),"",IF(_xlfn.MINIFS(Schneiddaten!$C$5:$C$304,Schneiddaten!$A$5:$A$304,$C$8,Schneiddaten!$B$5:$B$304,$E23,Schneiddaten!$C$5:$C$304,">="&M23)=0,"",SUMIFS(Schneiddaten!$D$5:$D$304,Schneiddaten!$A$5:$A$304,$C$8,Schneiddaten!$B$5:$B$304,$E23,Schneiddaten!$C$5:$C$304,_xlfn.MINIFS(Schneiddaten!$C$5:$C$304,Schneiddaten!$A$5:$A$304,$C$8,Schneiddaten!$B$5:$B$304,$E23,Schneiddaten!$C$5:$C$304,">="&M23)))) | W23: =IF(AND($D23="",$E23="",$F23="",$G23=""),"",IF(ISNA(MATCH($D23,lst_Profil,0)),"FEHLER: Profil unbekannt",IF(ISNA(MATCH($E23,lst_Werkstoff,0)),"FEHLER: Werkstoff unbekannt",IF(NOT(ISNUMBER(L23)),"FEHLER: Querschnitt fehlt (Profil)",IF(OR($F23="",$F23<=0),"FEHLER: Teilelänge fehlt",IF(OR($G23="",$G23<1),"FEHLER: Stückzahl fehlt",IF(NOT(ISNUMBER($H$4)),"FEHLER: Maschine fehlt/unbekannt",IF(Q23>$H$7,"FEHLER: Stange länger als Maschine zulässt",IF($F23+$H$6>T23,"FEHLER: Teil länger als Nutzlänge",IF(U23="nein","WARNUNG: kein gültiger Materialpreis",IF($H23="","HINWEIS: Schneidweg fehlt",IF(V23="","HINWEIS: keine Schneiddaten",IF(AND($AF23<>"",$AG23=""),"HINWEIS: Gewinde-Vorschlag prüfen","OK"))))))))))))) | X23: =IF(OR(O23="",$G23=""),"",O23*$G23)
K24: =IF($D24="","",IFERROR(INDEX(Profile!$B$5:$B$304,MATCH($D24,lst_Profil,0)),"")) | L24: =IF($D24="","",IFERROR(INDEX(Profile!$K$5:$K$304,MATCH($D24,lst_Profil,0))+0,"")) | M24: =IF($D24="","",IFERROR(INDEX(Profile!$E$5:$E$304,MATCH($D24,lst_Profil,0))+0,"")) | N24: =IF(OR(L24="",$E24=""),"",IFERROR(L24*INDEX(Werkstoffe!$E$5:$E$304,MATCH($E24,lst_Werkstoff,0))/1000,"")) | O24: =IF(OR(N24="",$F24=""),"",N24*$F24/1000) | P24: =IF(OR($F24="",$G24=""),"",$F24*$G24) | Q24: =IF($D24="","",IF($J24<>"",$J24,$C$9)) | R24: =IF($D24="","",IFERROR(IF(INDEX(Profile!$G$5:$G$304,MATCH($D24,lst_Profil,0))<>"",INDEX(Profile!$G$5:$G$304,MATCH($D24,lst_Profil,0)),$H$4),$H$4)) | S24: =IF($D24="","",IFERROR(IF(INDEX(Profile!$H$5:$H$304,MATCH($D24,lst_Profil,0))<>"",INDEX(Profile!$H$5:$H$304,MATCH($D24,lst_Profil,0)),$H$5),$H$5)) | T24: =IF(OR(Q24="",NOT(ISNUMBER(R24)),NOT(ISNUMBER(S24))),"",Q24-R24-S24) | U24: =IF(OR($D24="",$E24=""),"",IF(COUNTIFS(Preise!$A$5:$A$304,$D24,Preise!$B$5:$B$304,$E24,Preise!$I$5:$I$304,"OK")>0,"ja","nein")) | V24: =IF(OR(M24="",$E24="",$C$8=""),"",IF(_xlfn.MINIFS(Schneiddaten!$C$5:$C$304,Schneiddaten!$A$5:$A$304,$C$8,Schneiddaten!$B$5:$B$304,$E24,Schneiddaten!$C$5:$C$304,">="&M24)=0,"",SUMIFS(Schneiddaten!$D$5:$D$304,Schneiddaten!$A$5:$A$304,$C$8,Schneiddaten!$B$5:$B$304,$E24,Schneiddaten!$C$5:$C$304,_xlfn.MINIFS(Schneiddaten!$C$5:$C$304,Schneiddaten!$A$5:$A$304,$C$8,Schneiddaten!$B$5:$B$304,$E24,Schneiddaten!$C$5:$C$304,">="&M24)))) | W24: =IF(AND($D24="",$E24="",$F24="",$G24=""),"",IF(ISNA(MATCH($D24,lst_Profil,0)),"FEHLER: Profil unbekannt",IF(ISNA(MATCH($E24,lst_Werkstoff,0)),"FEHLER: Werkstoff unbekannt",IF(NOT(ISNUMBER(L24)),"FEHLER: Querschnitt fehlt (Profil)",IF(OR($F24="",$F24<=0),"FEHLER: Teilelänge fehlt",IF(OR($G24="",$G24<1),"FEHLER: Stückzahl fehlt",IF(NOT(ISNUMBER($H$4)),"FEHLER: Maschine fehlt/unbekannt",IF(Q24>$H$7,"FEHLER: Stange länger als Maschine zulässt",IF($F24+$H$6>T24,"FEHLER: Teil länger als Nutzlänge",IF(U24="nein","WARNUNG: kein gültiger Materialpreis",IF($H24="","HINWEIS: Schneidweg fehlt",IF(V24="","HINWEIS: keine Schneiddaten",IF(AND($AF24<>"",$AG24=""),"HINWEIS: Gewinde-Vorschlag prüfen","OK"))))))))))))) | X24: =IF(OR(O24="",$G24=""),"",O24*$G24)
K25: =IF($D25="","",IFERROR(INDEX(Profile!$B$5:$B$304,MATCH($D25,lst_Profil,0)),"")) | L25: =IF($D25="","",IFERROR(INDEX(Profile!$K$5:$K$304,MATCH($D25,lst_Profil,0))+0,"")) | M25: =IF($D25="","",IFERROR(INDEX(Profile!$E$5:$E$304,MATCH($D25,lst_Profil,0))+0,"")) | N25: =IF(OR(L25="",$E25=""),"",IFERROR(L25*INDEX(Werkstoffe!$E$5:$E$304,MATCH($E25,lst_Werkstoff,0))/1000,"")) | O25: =IF(OR(N25="",$F25=""),"",N25*$F25/1000) | P25: =IF(OR($F25="",$G25=""),"",$F25*$G25) | Q25: =IF($D25="","",IF($J25<>"",$J25,$C$9)) | R25: =IF($D25="","",IFERROR(IF(INDEX(Profile!$G$5:$G$304,MATCH($D25,lst_Profil,0))<>"",INDEX(Profile!$G$5:$G$304,MATCH($D25,lst_Profil,0)),$H$4),$H$4)) | S25: =IF($D25="","",IFERROR(IF(INDEX(Profile!$H$5:$H$304,MATCH($D25,lst_Profil,0))<>"",INDEX(Profile!$H$5:$H$304,MATCH($D25,lst_Profil,0)),$H$5),$H$5)) | T25: =IF(OR(Q25="",NOT(ISNUMBER(R25)),NOT(ISNUMBER(S25))),"",Q25-R25-S25) | U25: =IF(OR($D25="",$E25=""),"",IF(COUNTIFS(Preise!$A$5:$A$304,$D25,Preise!$B$5:$B$304,$E25,Preise!$I$5:$I$304,"OK")>0,"ja","nein")) | V25: =IF(OR(M25="",$E25="",$C$8=""),"",IF(_xlfn.MINIFS(Schneiddaten!$C$5:$C$304,Schneiddaten!$A$5:$A$304,$C$8,Schneiddaten!$B$5:$B$304,$E25,Schneiddaten!$C$5:$C$304,">="&M25)=0,"",SUMIFS(Schneiddaten!$D$5:$D$304,Schneiddaten!$A$5:$A$304,$C$8,Schneiddaten!$B$5:$B$304,$E25,Schneiddaten!$C$5:$C$304,_xlfn.MINIFS(Schneiddaten!$C$5:$C$304,Schneiddaten!$A$5:$A$304,$C$8,Schneiddaten!$B$5:$B$304,$E25,Schneiddaten!$C$5:$C$304,">="&M25)))) | W25: =IF(AND($D25="",$E25="",$F25="",$G25=""),"",IF(ISNA(MATCH($D25,lst_Profil,0)),"FEHLER: Profil unbekannt",IF(ISNA(MATCH($E25,lst_Werkstoff,0)),"FEHLER: Werkstoff unbekannt",IF(NOT(ISNUMBER(L25)),"FEHLER: Querschnitt fehlt (Profil)",IF(OR($F25="",$F25<=0),"FEHLER: Teilelänge fehlt",IF(OR($G25="",$G25<1),"FEHLER: Stückzahl fehlt",IF(NOT(ISNUMBER($H$4)),"FEHLER: Maschine fehlt/unbekannt",IF(Q25>$H$7,"FEHLER: Stange länger als Maschine zulässt",IF($F25+$H$6>T25,"FEHLER: Teil länger als Nutzlänge",IF(U25="nein","WARNUNG: kein gültiger Materialpreis",IF($H25="","HINWEIS: Schneidweg fehlt",IF(V25="","HINWEIS: keine Schneiddaten",IF(AND($AF25<>"",$AG25=""),"HINWEIS: Gewinde-Vorschlag prüfen","OK"))))))))))))) | X25: =IF(OR(O25="",$G25=""),"",O25*$G25)
K26: =IF($D26="","",IFERROR(INDEX(Profile!$B$5:$B$304,MATCH($D26,lst_Profil,0)),"")) | L26: =IF($D26="","",IFERROR(INDEX(Profile!$K$5:$K$304,MATCH($D26,lst_Profil,0))+0,"")) | M26: =IF($D26="","",IFERROR(INDEX(Profile!$E$5:$E$304,MATCH($D26,lst_Profil,0))+0,"")) | N26: =IF(OR(L26="",$E26=""),"",IFERROR(L26*INDEX(Werkstoffe!$E$5:$E$304,MATCH($E26,lst_Werkstoff,0))/1000,"")) | O26: =IF(OR(N26="",$F26=""),"",N26*$F26/1000) | P26: =IF(OR($F26="",$G26=""),"",$F26*$G26) | Q26: =IF($D26="","",IF($J26<>"",$J26,$C$9)) | R26: =IF($D26="","",IFERROR(IF(INDEX(Profile!$G$5:$G$304,MATCH($D26,lst_Profil,0))<>"",INDEX(Profile!$G$5:$G$304,MATCH($D26,lst_Profil,0)),$H$4),$H$4)) | S26: =IF($D26="","",IFERROR(IF(INDEX(Profile!$H$5:$H$304,MATCH($D26,lst_Profil,0))<>"",INDEX(Profile!$H$5:$H$304,MATCH($D26,lst_Profil,0)),$H$5),$H$5)) | T26: =IF(OR(Q26="",NOT(ISNUMBER(R26)),NOT(ISNUMBER(S26))),"",Q26-R26-S26) | U26: =IF(OR($D26="",$E26=""),"",IF(COUNTIFS(Preise!$A$5:$A$304,$D26,Preise!$B$5:$B$304,$E26,Preise!$I$5:$I$304,"OK")>0,"ja","nein")) | V26: =IF(OR(M26="",$E26="",$C$8=""),"",IF(_xlfn.MINIFS(Schneiddaten!$C$5:$C$304,Schneiddaten!$A$5:$A$304,$C$8,Schneiddaten!$B$5:$B$304,$E26,Schneiddaten!$C$5:$C$304,">="&M26)=0,"",SUMIFS(Schneiddaten!$D$5:$D$304,Schneiddaten!$A$5:$A$304,$C$8,Schneiddaten!$B$5:$B$304,$E26,Schneiddaten!$C$5:$C$304,_xlfn.MINIFS(Schneiddaten!$C$5:$C$304,Schneiddaten!$A$5:$A$304,$C$8,Schneiddaten!$B$5:$B$304,$E26,Schneiddaten!$C$5:$C$304,">="&M26)))) | W26: =IF(AND($D26="",$E26="",$F26="",$G26=""),"",IF(ISNA(MATCH($D26,lst_Profil,0)),"FEHLER: Profil unbekannt",IF(ISNA(MATCH($E26,lst_Werkstoff,0)),"FEHLER: Werkstoff unbekannt",IF(NOT(ISNUMBER(L26)),"FEHLER: Querschnitt fehlt (Profil)",IF(OR($F26="",$F26<=0),"FEHLER: Teilelänge fehlt",IF(OR($G26="",$G26<1),"FEHLER: Stückzahl fehlt",IF(NOT(ISNUMBER($H$4)),"FEHLER: Maschine fehlt/unbekannt",IF(Q26>$H$7,"FEHLER: Stange länger als Maschine zulässt",IF($F26+$H$6>T26,"FEHLER: Teil länger als Nutzlänge",IF(U26="nein","WARNUNG: kein gültiger Materialpreis",IF($H26="","HINWEIS: Schneidweg fehlt",IF(V26="","HINWEIS: keine Schneiddaten",IF(AND($AF26<>"",$AG26=""),"HINWEIS: Gewinde-Vorschlag prüfen","OK"))))))))))))) | X26: =IF(OR(O26="",$G26=""),"",O26*$G26)
K27: =IF($D27="","",IFERROR(INDEX(Profile!$B$5:$B$304,MATCH($D27,lst_Profil,0)),"")) | L27: =IF($D27="","",IFERROR(INDEX(Profile!$K$5:$K$304,MATCH($D27,lst_Profil,0))+0,"")) | M27: =IF($D27="","",IFERROR(INDEX(Profile!$E$5:$E$304,MATCH($D27,lst_Profil,0))+0,"")) | N27: =IF(OR(L27="",$E27=""),"",IFERROR(L27*INDEX(Werkstoffe!$E$5:$E$304,MATCH($E27,lst_Werkstoff,0))/1000,"")) | O27: =IF(OR(N27="",$F27=""),"",N27*$F27/1000) | P27: =IF(OR($F27="",$G27=""),"",$F27*$G27) | Q27: =IF($D27="","",IF($J27<>"",$J27,$C$9)) | R27: =IF($D27="","",IFERROR(IF(INDEX(Profile!$G$5:$G$304,MATCH($D27,lst_Profil,0))<>"",INDEX(Profile!$G$5:$G$304,MATCH($D27,lst_Profil,0)),$H$4),$H$4)) | S27: =IF($D27="","",IFERROR(IF(INDEX(Profile!$H$5:$H$304,MATCH($D27,lst_Profil,0))<>"",INDEX(Profile!$H$5:$H$304,MATCH($D27,lst_Profil,0)),$H$5),$H$5)) | T27: =IF(OR(Q27="",NOT(ISNUMBER(R27)),NOT(ISNUMBER(S27))),"",Q27-R27-S27) | U27: =IF(OR($D27="",$E27=""),"",IF(COUNTIFS(Preise!$A$5:$A$304,$D27,Preise!$B$5:$B$304,$E27,Preise!$I$5:$I$304,"OK")>0,"ja","nein")) | V27: =IF(OR(M27="",$E27="",$C$8=""),"",IF(_xlfn.MINIFS(Schneiddaten!$C$5:$C$304,Schneiddaten!$A$5:$A$304,$C$8,Schneiddaten!$B$5:$B$304,$E27,Schneiddaten!$C$5:$C$304,">="&M27)=0,"",SUMIFS(Schneiddaten!$D$5:$D$304,Schneiddaten!$A$5:$A$304,$C$8,Schneiddaten!$B$5:$B$304,$E27,Schneiddaten!$C$5:$C$304,_xlfn.MINIFS(Schneiddaten!$C$5:$C$304,Schneiddaten!$A$5:$A$304,$C$8,Schneiddaten!$B$5:$B$304,$E27,Schneiddaten!$C$5:$C$304,">="&M27)))) | W27: =IF(AND($D27="",$E27="",$F27="",$G27=""),"",IF(ISNA(MATCH($D27,lst_Profil,0)),"FEHLER: Profil unbekannt",IF(ISNA(MATCH($E27,lst_Werkstoff,0)),"FEHLER: Werkstoff unbekannt",IF(NOT(ISNUMBER(L27)),"FEHLER: Querschnitt fehlt (Profil)",IF(OR($F27="",$F27<=0),"FEHLER: Teilelänge fehlt",IF(OR($G27="",$G27<1),"FEHLER: Stückzahl fehlt",IF(NOT(ISNUMBER($H$4)),"FEHLER: Maschine fehlt/unbekannt",IF(Q27>$H$7,"FEHLER: Stange länger als Maschine zulässt",IF($F27+$H$6>T27,"FEHLER: Teil länger als Nutzlänge",IF(U27="nein","WARNUNG: kein gültiger Materialpreis",IF($H27="","HINWEIS: Schneidweg fehlt",IF(V27="","HINWEIS: keine Schneiddaten",IF(AND($AF27<>"",$AG27=""),"HINWEIS: Gewinde-Vorschlag prüfen","OK"))))))))))))) | X27: =IF(OR(O27="",$G27=""),"",O27*$G27)
K28: =IF($D28="","",IFERROR(INDEX(Profile!$B$5:$B$304,MATCH($D28,lst_Profil,0)),"")) | L28: =IF($D28="","",IFERROR(INDEX(Profile!$K$5:$K$304,MATCH($D28,lst_Profil,0))+0,"")) | M28: =IF($D28="","",IFERROR(INDEX(Profile!$E$5:$E$304,MATCH($D28,lst_Profil,0))+0,"")) | N28: =IF(OR(L28="",$E28=""),"",IFERROR(L28*INDEX(Werkstoffe!$E$5:$E$304,MATCH($E28,lst_Werkstoff,0))/1000,"")) | O28: =IF(OR(N28="",$F28=""),"",N28*$F28/1000) | P28: =IF(OR($F28="",$G28=""),"",$F28*$G28) | Q28: =IF($D28="","",IF($J28<>"",$J28,$C$9)) | R28: =IF($D28="","",IFERROR(IF(INDEX(Profile!$G$5:$G$304,MATCH($D28,lst_Profil,0))<>"",INDEX(Profile!$G$5:$G$304,MATCH($D28,lst_Profil,0)),$H$4),$H$4)) | S28: =IF($D28="","",IFERROR(IF(INDEX(Profile!$H$5:$H$304,MATCH($D28,lst_Profil,0))<>"",INDEX(Profile!$H$5:$H$304,MATCH($D28,lst_Profil,0)),$H$5),$H$5)) | T28: =IF(OR(Q28="",NOT(ISNUMBER(R28)),NOT(ISNUMBER(S28))),"",Q28-R28-S28) | U28: =IF(OR($D28="",$E28=""),"",IF(COUNTIFS(Preise!$A$5:$A$304,$D28,Preise!$B$5:$B$304,$E28,Preise!$I$5:$I$304,"OK")>0,"ja","nein")) | V28: =IF(OR(M28="",$E28="",$C$8=""),"",IF(_xlfn.MINIFS(Schneiddaten!$C$5:$C$304,Schneiddaten!$A$5:$A$304,$C$8,Schneiddaten!$B$5:$B$304,$E28,Schneiddaten!$C$5:$C$304,">="&M28)=0,"",SUMIFS(Schneiddaten!$D$5:$D$304,Schneiddaten!$A$5:$A$304,$C$8,Schneiddaten!$B$5:$B$304,$E28,Schneiddaten!$C$5:$C$304,_xlfn.MINIFS(Schneiddaten!$C$5:$C$304,Schneiddaten!$A$5:$A$304,$C$8,Schneiddaten!$B$5:$B$304,$E28,Schneiddaten!$C$5:$C$304,">="&M28)))) | W28: =IF(AND($D28="",$E28="",$F28="",$G28=""),"",IF(ISNA(MATCH($D28,lst_Profil,0)),"FEHLER: Profil unbekannt",IF(ISNA(MATCH($E28,lst_Werkstoff,0)),"FEHLER: Werkstoff unbekannt",IF(NOT(ISNUMBER(L28)),"FEHLER: Querschnitt fehlt (Profil)",IF(OR($F28="",$F28<=0),"FEHLER: Teilelänge fehlt",IF(OR($G28="",$G28<1),"FEHLER: Stückzahl fehlt",IF(NOT(ISNUMBER($H$4)),"FEHLER: Maschine fehlt/unbekannt",IF(Q28>$H$7,"FEHLER: Stange länger als Maschine zulässt",IF($F28+$H$6>T28,"FEHLER: Teil länger als Nutzlänge",IF(U28="nein","WARNUNG: kein gültiger Materialpreis",IF($H28="","HINWEIS: Schneidweg fehlt",IF(V28="","HINWEIS: keine Schneiddaten",IF(AND($AF28<>"",$AG28=""),"HINWEIS: Gewinde-Vorschlag prüfen","OK"))))))))))))) | X28: =IF(OR(O28="",$G28=""),"",O28*$G28)
K29: =IF($D29="","",IFERROR(INDEX(Profile!$B$5:$B$304,MATCH($D29,lst_Profil,0)),"")) | L29: =IF($D29="","",IFERROR(INDEX(Profile!$K$5:$K$304,MATCH($D29,lst_Profil,0))+0,"")) | M29: =IF($D29="","",IFERROR(INDEX(Profile!$E$5:$E$304,MATCH($D29,lst_Profil,0))+0,"")) | N29: =IF(OR(L29="",$E29=""),"",IFERROR(L29*INDEX(Werkstoffe!$E$5:$E$304,MATCH($E29,lst_Werkstoff,0))/1000,"")) | O29: =IF(OR(N29="",$F29=""),"",N29*$F29/1000) | P29: =IF(OR($F29="",$G29=""),"",$F29*$G29) | Q29: =IF($D29="","",IF($J29<>"",$J29,$C$9)) | R29: =IF($D29="","",IFERROR(IF(INDEX(Profile!$G$5:$G$304,MATCH($D29,lst_Profil,0))<>"",INDEX(Profile!$G$5:$G$304,MATCH($D29,lst_Profil,0)),$H$4),$H$4)) | S29: =IF($D29="","",IFERROR(IF(INDEX(Profile!$H$5:$H$304,MATCH($D29,lst_Profil,0))<>"",INDEX(Profile!$H$5:$H$304,MATCH($D29,lst_Profil,0)),$H$5),$H$5)) | T29: =IF(OR(Q29="",NOT(ISNUMBER(R29)),NOT(ISNUMBER(S29))),"",Q29-R29-S29) | U29: =IF(OR($D29="",$E29=""),"",IF(COUNTIFS(Preise!$A$5:$A$304,$D29,Preise!$B$5:$B$304,$E29,Preise!$I$5:$I$304,"OK")>0,"ja","nein")) | V29: =IF(OR(M29="",$E29="",$C$8=""),"",IF(_xlfn.MINIFS(Schneiddaten!$C$5:$C$304,Schneiddaten!$A$5:$A$304,$C$8,Schneiddaten!$B$5:$B$304,$E29,Schneiddaten!$C$5:$C$304,">="&M29)=0,"",SUMIFS(Schneiddaten!$D$5:$D$304,Schneiddaten!$A$5:$A$304,$C$8,Schneiddaten!$B$5:$B$304,$E29,Schneiddaten!$C$5:$C$304,_xlfn.MINIFS(Schneiddaten!$C$5:$C$304,Schneiddaten!$A$5:$A$304,$C$8,Schneiddaten!$B$5:$B$304,$E29,Schneiddaten!$C$5:$C$304,">="&M29)))) | W29: =IF(AND($D29="",$E29="",$F29="",$G29=""),"",IF(ISNA(MATCH($D29,lst_Profil,0)),"FEHLER: Profil unbekannt",IF(ISNA(MATCH($E29,lst_Werkstoff,0)),"FEHLER: Werkstoff unbekannt",IF(NOT(ISNUMBER(L29)),"FEHLER: Querschnitt fehlt (Profil)",IF(OR($F29="",$F29<=0),"FEHLER: Teilelänge fehlt",IF(OR($G29="",$G29<1),"FEHLER: Stückzahl fehlt",IF(NOT(ISNUMBER($H$4)),"FEHLER: Maschine fehlt/unbekannt",IF(Q29>$H$7,"FEHLER: Stange länger als Maschine zulässt",IF($F29+$H$6>T29,"FEHLER: Teil länger als Nutzlänge",IF(U29="nein","WARNUNG: kein gültiger Materialpreis",IF($H29="","HINWEIS: Schneidweg fehlt",IF(V29="","HINWEIS: keine Schneiddaten",IF(AND($AF29<>"",$AG29=""),"HINWEIS: Gewinde-Vorschlag prüfen","OK"))))))))))))) | X29: =IF(OR(O29="",$G29=""),"",O29*$G29)
... K512: =IF($D512="","",IFERROR(INDEX(Profile!$B$5:$B$304,MATCH($D512,lst_Profil,0)),"")) | L512: =IF($D512="","",IFERROR(INDEX(Profile!$K$5:$K$304,MATCH($D512,lst_Profil,0))+0,"")) | M512: =IF($D512="","",IFERROR(INDEX(Profile!$E$5:$E$304,MATCH($D512,lst_Profil,0))+0,"")) | N512: =IF(OR(L512="",$E512=""),"",IFERROR(L512*INDEX(Werkstoffe!$E$5:$E$304,MATCH($E512,lst_Werkstoff,0))/1000,"")) | O512: =IF(OR(N512="",$F512=""),"",N512*$F512/1000) | P512: =IF(OR($F512="",$G512=""),"",$F512*$G512) | Q512: =IF($D512="","",IF($J512<>"",$J512,$C$9)) | R512: =IF($D512="","",IFERROR(IF(INDEX(Profile!$G$5:$G$304,MATCH($D512,lst_Profil,0))<>"",INDEX(Profile!$G$5:$G$304,MATCH($D512,lst_Profil,0)),$H$4),$H$4)) | S512: =IF($D512="","",IFERROR(IF(INDEX(Profile!$H$5:$H$304,MATCH($D512,lst_Profil,0))<>"",INDEX(Profile!$H$5:$H$304,MATCH($D512,lst_Profil,0)),$H$5),$H$5)) | T512: =IF(OR(Q512="",NOT(ISNUMBER(R512)),NOT(ISNUMBER(S512))),"",Q512-R512-S512) | U512: =IF(OR($D512="",$E512=""),"",IF(COUNTIFS(Preise!$A$5:$A$304,$D512,Preise!$B$5:$B$304,$E512,Preise!$I$5:$I$304,"OK")>0,"ja","nein")) | V512: =IF(OR(M512="",$E512="",$C$8=""),"",IF(_xlfn.MINIFS(Schneiddaten!$C$5:$C$304,Schneiddaten!$A$5:$A$304,$C$8,Schneiddaten!$B$5:$B$304,$E512,Schneiddaten!$C$5:$C$304,">="&M512)=0,"",SUMIFS(Schneiddaten!$D$5:$D$304,Schneiddaten!$A$5:$A$304,$C$8,Schneiddaten!$B$5:$B$304,$E512,Schneiddaten!$C$5:$C$304,_xlfn.MINIFS(Schneiddaten!$C$5:$C$304,Schneiddaten!$A$5:$A$304,$C$8,Schneiddaten!$B$5:$B$304,$E512,Schneiddaten!$C$5:$C$304,">="&M512)))) | W512: =IF(AND($D512="",$E512="",$F512="",$G512=""),"",IF(ISNA(MATCH($D512,lst_Profil,0)),"FEHLER: Profil unbekannt",IF(ISNA(MATCH($E512,lst_Werkstoff,0)),"FEHLER: Werkstoff unbekannt",IF(NOT(ISNUMBER(L512)),"FEHLER: Querschnitt fehlt (Profil)",IF(OR($F512="",$F512<=0),"FEHLER: Teilelänge fehlt",IF(OR($G512="",$G512<1),"FEHLER: Stückzahl fehlt",IF(NOT(ISNUMBER($H$4)),"FEHLER: Maschine fehlt/unbekannt",IF(Q512>$H$7,"FEHLER: Stange länger als Maschine zulässt",IF($F512+$H$6>T512,"FEHLER: Teil länger als Nutzlänge",IF(U512="nein","WARNUNG: kein gültiger Materialpreis",IF($H512="","HINWEIS: Schneidweg fehlt",IF(V512="","HINWEIS: keine Schneiddaten",IF(AND($AF512<>"",$AG512=""),"HINWEIS: Gewinde-Vorschlag prüfen","OK"))))))))))))) | X512: =IF(OR(O512="",$G512=""),"",O512*$G512)

Sheet Listen
A1: Auswahllisten
A2: Werte für Dropdowns. Ergänzungen hier eintragen.
A4: Profilform | B4: Preisbasis | C4: Ja/Nein
A5: Rundrohr | B5: €/kg | C5: ja
A6: Quadratrohr | B6: €/Stange | C6: nein
A7: Rechteckrohr
A8: Sonderprofil

Sheet Profile
A1: Profile / Abmessungen
A2: Abmessung A = Ø (Rundrohr) bzw. Breite; Abmessung B = Höhe (nur Rechteckrohr). Endbeschnitt/Greiferrest nur eintragen, wenn vom Maschinenwert abweichend.
A4: Profil-ID | B4: Profilform | C4: Abmessung A [mm] | D4: Abmessung B [mm] | E4: Wandstärke [mm] | F4: Fläche manuell [mm²] (optional) | G4: Endbeschnitt abweichend [mm] | H4: Greiferrest abweichend [mm] | I4: Bemerkung | J4: Fläche berechnet [mm²] | K4: Fläche wirksam [mm²]
A5: RR 42,4x2,0 | B5: Rundrohr | C5: 42.4 | E5: 2 | I5: Beispiel | J5: =IF(OR(A5="",C5="",E5=""),"",IF(B5="Rundrohr",PI()/4*(C5^2-(C5-2*E5)^2),IF(OR(B5="Quadratrohr",AND(B5="Rechteckrohr",D5<>"")),C5*IF(B5="Quadratrohr",C5,D5)-(C5-2*E5)*(IF(B5="Quadratrohr",C5,D5)-2*E5),""))) -> 253.84069 | K5: =IF(A5="","",IF(F5<>"",F5,J5)) -> 253.84069
A6: RR 48,3x2,6 | B6: Rundrohr | C6: 48.3 | E6: 2.6 | I6: Beispiel | J6: =IF(OR(A6="",C6="",E6=""),"",IF(B6="Rundrohr",PI()/4*(C6^2-(C6-2*E6)^2),IF(OR(B6="Quadratrohr",AND(B6="Rechteckrohr",D6<>"")),C6*IF(B6="Quadratrohr",C6,D6)-(C6-2*E6)*(IF(B6="Quadratrohr",C6,D6)-2*E6),""))) -> 373.28404 | K6: =IF(A6="","",IF(F6<>"",F6,J6)) -> 373.28404
A7: QR 40x40x3 | B7: Quadratrohr | C7: 40 | E7: 3 | I7: Beispiel | J7: =IF(OR(A7="",C7="",E7=""),"",IF(B7="Rundrohr",PI()/4*(C7^2-(C7-2*E7)^2),IF(OR(B7="Quadratrohr",AND(B7="Rechteckrohr",D7<>"")),C7*IF(B7="Quadratrohr",C7,D7)-(C7-2*E7)*(IF(B7="Quadratrohr",C7,D7)-2*E7),""))) -> 444 | K7: =IF(A7="","",IF(F7<>"",F7,J7)) -> 444
A8: RE 60x40x3 | B8: Rechteckrohr | C8: 60 | D8: 40 | E8: 3 | I8: Beispiel | J8: =IF(OR(A8="",C8="",E8=""),"",IF(B8="Rundrohr",PI()/4*(C8^2-(C8-2*E8)^2),IF(OR(B8="Quadratrohr",AND(B8="Rechteckrohr",D8<>"")),C8*IF(B8="Quadratrohr",C8,D8)-(C8-2*E8)*(IF(B8="Quadratrohr",C8,D8)-2*E8),""))) -> 564 | K8: =IF(A8="","",IF(F8<>"",F8,J8)) -> 564
A9: RE 120x60x4 | B9: Rechteckrohr | C9: 120 | D9: 60 | E9: 4 | G9: 30 | H9: 120 | I9: Beispiel: profilspezifischer Endbeschnitt/Greiferrest | J9: =IF(OR(A9="",C9="",E9=""),"",IF(B9="Rundrohr",PI()/4*(C9^2-(C9-2*E9)^2),IF(OR(B9="Quadratrohr",AND(B9="Rechteckrohr",D9<>"")),C9*IF(B9="Quadratrohr",C9,D9)-(C9-2*E9)*(IF(B9="Quadratrohr",C9,D9)-2*E9),""))) -> 1376 | K9: =IF(A9="","",IF(F9<>"",F9,J9)) -> 1376
J10: =IF(OR(A10="",C10="",E10=""),"",IF(B10="Rundrohr",PI()/4*(C10^2-(C10-2*E10)^2),IF(OR(B10="Quadratrohr",AND(B10="Rechteckrohr",D10<>"")),C10*IF(B10="Quadratrohr",C10,D10)-(C10-2*E10)*(IF(B10="Quadratrohr",C10,D10)-2*E10),""))) | K10: =IF(A10="","",IF(F10<>"",F10,J10))
J11: =IF(OR(A11="",C11="",E11=""),"",IF(B11="Rundrohr",PI()/4*(C11^2-(C11-2*E11)^2),IF(OR(B11="Quadratrohr",AND(B11="Rechteckrohr",D11<>"")),C11*IF(B11="Quadratrohr",C11,D11)-(C11-2*E11)*(IF(B11="Quadratrohr",C11,D11)-2*E11),""))) | K11: =IF(A11="","",IF(F11<>"",F11,J11))
J12: =IF(OR(A12="",C12="",E12=""),"",IF(B12="Rundrohr",PI()/4*(C12^2-(C12-2*E12)^2),IF(OR(B12="Quadratrohr",AND(B12="Rechteckrohr",D12<>"")),C12*IF(B12="Quadratrohr",C12,D12)-(C12-2*E12)*(IF(B12="Quadratrohr",C12,D12)-2*E12),""))) | K12: =IF(A12="","",IF(F12<>"",F12,J12))
J13: =IF(OR(A13="",C13="",E13=""),"",IF(B13="Rundrohr",PI()/4*(C13^2-(C13-2*E13)^2),IF(OR(B13="Quadratrohr",AND(B13="Rechteckrohr",D13<>"")),C13*IF(B13="Quadratrohr",C13,D13)-(C13-2*E13)*(IF(B13="Quadratrohr",C13,D13)-2*E13),""))) | K13: =IF(A13="","",IF(F13<>"",F13,J13))
J14: =IF(OR(A14="",C14="",E14=""),"",IF(B14="Rundrohr",PI()/4*(C14^2-(C14-2*E14)^2),IF(OR(B14="Quadratrohr",AND(B14="Rechteckrohr",D14<>"")),C14*IF(B14="Quadratrohr",C14,D14)-(C14-2*E14)*(IF(B14="Quadratrohr",C14,D14)-2*E14),""))) | K14: =IF(A14="","",IF(F14<>"",F14,J14))
J15: =IF(OR(A15="",C15="",E15=""),"",IF(B15="Rundrohr",PI()/4*(C15^2-(C15-2*E15)^2),IF(OR(B15="Quadratrohr",AND(B15="Rechteckrohr",D15<>"")),C15*IF(B15="Quadratrohr",C15,D15)-(C15-2*E15)*(IF(B15="Quadratrohr",C15,D15)-2*E15),""))) | K15: =IF(A15="","",IF(F15<>"",F15,J15))
J16: =IF(OR(A16="",C16="",E16=""),"",IF(B16="Rundrohr",PI()/4*(C16^2-(C16-2*E16)^2),IF(OR(B16="Quadratrohr",AND(B16="Rechteckrohr",D16<>"")),C16*IF(B16="Quadratrohr",C16,D16)-(C16-2*E16)*(IF(B16="Quadratrohr",C16,D16)-2*E16),""))) | K16: =IF(A16="","",IF(F16<>"",F16,J16))
J17: =IF(OR(A17="",C17="",E17=""),"",IF(B17="Rundrohr",PI()/4*(C17^2-(C17-2*E17)^2),IF(OR(B17="Quadratrohr",AND(B17="Rechteckrohr",D17<>"")),C17*IF(B17="Quadratrohr",C17,D17)-(C17-2*E17)*(IF(B17="Quadratrohr",C17,D17)-2*E17),""))) | K17: =IF(A17="","",IF(F17<>"",F17,J17))
J18: =IF(OR(A18="",C18="",E18=""),"",IF(B18="Rundrohr",PI()/4*(C18^2-(C18-2*E18)^2),IF(OR(B18="Quadratrohr",AND(B18="Rechteckrohr",D18<>"")),C18*IF(B18="Quadratrohr",C18,D18)-(C18-2*E18)*(IF(B18="Quadratrohr",C18,D18)-2*E18),""))) | K18: =IF(A18="","",IF(F18<>"",F18,J18))
J19: =IF(OR(A19="",C19="",E19=""),"",IF(B19="Rundrohr",PI()/4*(C19^2-(C19-2*E19)^2),IF(OR(B19="Quadratrohr",AND(B19="Rechteckrohr",D19<>"")),C19*IF(B19="Quadratrohr",C19,D19)-(C19-2*E19)*(IF(B19="Quadratrohr",C19,D19)-2*E19),""))) | K19: =IF(A19="","",IF(F19<>"",F19,J19))
J20: =IF(OR(A20="",C20="",E20=""),"",IF(B20="Rundrohr",PI()/4*(C20^2-(C20-2*E20)^2),IF(OR(B20="Quadratrohr",AND(B20="Rechteckrohr",D20<>"")),C20*IF(B20="Quadratrohr",C20,D20)-(C20-2*E20)*(IF(B20="Quadratrohr",C20,D20)-2*E20),""))) | K20: =IF(A20="","",IF(F20<>"",F20,J20))
J21: =IF(OR(A21="",C21="",E21=""),"",IF(B21="Rundrohr",PI()/4*(C21^2-(C21-2*E21)^2),IF(OR(B21="Quadratrohr",AND(B21="Rechteckrohr",D21<>"")),C21*IF(B21="Quadratrohr",C21,D21)-(C21-2*E21)*(IF(B21="Quadratrohr",C21,D21)-2*E21),""))) | K21: =IF(A21="","",IF(F21<>"",F21,J21))
... J304: =IF(OR(A304="",C304="",E304=""),"",IF(B304="Rundrohr",PI()/4*(C304^2-(C304-2*E304)^2),IF(OR(B304="Quadratrohr",AND(B304="Rechteckrohr",D304<>"")),C304*IF(B304="Quadratrohr",C304,D304)-(C304-2*E304)*(IF(B304="Quadratrohr",C304,D304)-2*E304),""))) | K304: =IF(A304="","",IF(F304<>"",F304,J304))

Sheet Werkstoffe
A1: Werkstoffe / Materialqualität
A2: Werkstoff-ID ist der Schlüssel für Preise, Schneiddaten und Auftrag. Beispielwerte ersetzen.
A4: Werkstoff-ID | B4: Werkstoff | C4: Werkstoff-Nr. | D4: Norm / Qualität | E4: Dichte [kg/dm³] | F4: Bemerkung
A5: S235-10219 | B5: S235JRH | C5: 1.0039 | D5: EN 10219 kaltgefertigt, geschweißt | E5: 7.85 | F5: Beispiel
A6: S355-10219 | B6: S355J2H | C6: 1.0576 | D6: EN 10219 kaltgefertigt, geschweißt | E6: 7.85 | F6: Beispiel
A7: 1.4301 | B7: X5CrNi18-10 | C7: 1.4301 | D7: EN 10217-7 / ASTM A554 | E7: 7.9 | F7: Beispiel
A8: AW6060-T66 | B8: EN AW-6060 T66 | C8: 3.3206 | D8: EN 755-2 | E8: 2.7 | F8: Beispiel

Sheet Preise
A1: Materialpreise
A2: Je Kombination Profil + Werkstoff genau eine Zeile. Preisbasis €/kg oder €/Stange (bezogen auf die Liefer-Stangenlänge).
A4: Profil-ID | B4: Werkstoff-ID | C4: Preisbasis | D4: Preis [€] | E4: Liefer-Stangenlänge [mm] | F4: Gültig ab | G4: Lieferant | H4: Bemerkung | I4: Prüfung
A5: RR 42,4x2,0 | B5: S235-10219 | C5: €/kg | D5: 1.45 | E5: 6000 | F5: 46296 | G5: Beispiel-Lieferant | H5: Beispiel | I5: =IF(A5&B5="","",IF(ISNA(MATCH(A5,lst_Profil,0)),"FEHLER: Profil unbekannt",IF(ISNA(MATCH(B5,lst_Werkstoff,0)),"FEHLER: Werkstoff unbekannt",IF(COUNTIFS($A$5:$A$304,A5,$B$5:$B$304,B5)>1,"FEHLER: doppelt",IF(OR(C5="",D5=""),"FEHLER: Preis unvollständig",IF(AND(C5="€/Stange",E5=""),"FEHLER: Stangenlänge fehlt","OK")))))) -> OK
A6: RR 48,3x2,6 | B6: S235-10219 | C6: €/kg | D6: 1.45 | E6: 6000 | F6: 46296 | G6: Beispiel-Lieferant | H6: Beispiel | I6: =IF(A6&B6="","",IF(ISNA(MATCH(A6,lst_Profil,0)),"FEHLER: Profil unbekannt",IF(ISNA(MATCH(B6,lst_Werkstoff,0)),"FEHLER: Werkstoff unbekannt",IF(COUNTIFS($A$5:$A$304,A6,$B$5:$B$304,B6)>1,"FEHLER: doppelt",IF(OR(C6="",D6=""),"FEHLER: Preis unvollständig",IF(AND(C6="€/Stange",E6=""),"FEHLER: Stangenlänge fehlt","OK")))))) -> OK
A7: QR 40x40x3 | B7: S235-10219 | C7: €/kg | D7: 1.5 | E7: 6000 | F7: 46296 | G7: Beispiel-Lieferant | H7: Beispiel | I7: =IF(A7&B7="","",IF(ISNA(MATCH(A7,lst_Profil,0)),"FEHLER: Profil unbekannt",IF(ISNA(MATCH(B7,lst_Werkstoff,0)),"FEHLER: Werkstoff unbekannt",IF(COUNTIFS($A$5:$A$304,A7,$B$5:$B$304,B7)>1,"FEHLER: doppelt",IF(OR(C7="",D7=""),"FEHLER: Preis unvollständig",IF(AND(C7="€/Stange",E7=""),"FEHLER: Stangenlänge fehlt","OK")))))) -> OK
A8: RE 60x40x3 | B8: S355-10219 | C8: €/kg | D8: 1.6 | E8: 6000 | F8: 46296 | G8: Beispiel-Lieferant | H8: Beispiel | I8: =IF(A8&B8="","",IF(ISNA(MATCH(A8,lst_Profil,0)),"FEHLER: Profil unbekannt",IF(ISNA(MATCH(B8,lst_Werkstoff,0)),"FEHLER: Werkstoff unbekannt",IF(COUNTIFS($A$5:$A$304,A8,$B$5:$B$304,B8)>1,"FEHLER: doppelt",IF(OR(C8="",D8=""),"FEHLER: Preis unvollständig",IF(AND(C8="€/Stange",E8=""),"FEHLER: Stangenlänge fehlt","OK")))))) -> OK
A9: RR 42,4x2,0 | B9: 1.4301 | C9: €/Stange | D9: 62 | E9: 6000 | F9: 46296 | G9: Beispiel-Lieferant | H9: Beispiel | I9: =IF(A9&B9="","",IF(ISNA(MATCH(A9,lst_Profil,0)),"FEHLER: Profil unbekannt",IF(ISNA(MATCH(B9,lst_Werkstoff,0)),"FEHLER: Werkstoff unbekannt",IF(COUNTIFS($A$5:$A$304,A9,$B$5:$B$304,B9)>1,"FEHLER: doppelt",IF(OR(C9="",D9=""),"FEHLER: Preis unvollständig",IF(AND(C9="€/Stange",E9=""),"FEHLER: Stangenlänge fehlt","OK")))))) -> OK
I10: =IF(A10&B10="","",IF(ISNA(MATCH(A10,lst_Profil,0)),"FEHLER: Profil unbekannt",IF(ISNA(MATCH(B10,lst_Werkstoff,0)),"FEHLER: Werkstoff unbekannt",IF(COUNTIFS($A$5:$A$304,A10,$B$5:$B$304,B10)>1,"FEHLER: doppelt",IF(OR(C10="",D10=""),"FEHLER: Preis unvollständig",IF(AND(C10="€/Stange",E10=""),"FEHLER: Stangenlänge fehlt","OK"))))))
I11: =IF(A11&B11="","",IF(ISNA(MATCH(A11,lst_Profil,0)),"FEHLER: Profil unbekannt",IF(ISNA(MATCH(B11,lst_Werkstoff,0)),"FEHLER: Werkstoff unbekannt",IF(COUNTIFS($A$5:$A$304,A11,$B$5:$B$304,B11)>1,"FEHLER: doppelt",IF(OR(C11="",D11=""),"FEHLER: Preis unvollständig",IF(AND(C11="€/Stange",E11=""),"FEHLER: Stangenlänge fehlt","OK"))))))
I12: =IF(A12&B12="","",IF(ISNA(MATCH(A12,lst_Profil,0)),"FEHLER: Profil unbekannt",IF(ISNA(MATCH(B12,lst_Werkstoff,0)),"FEHLER: Werkstoff unbekannt",IF(COUNTIFS($A$5:$A$304,A12,$B$5:$B$304,B12)>1,"FEHLER: doppelt",IF(OR(C12="",D12=""),"FEHLER: Preis unvollständig",IF(AND(C12="€/Stange",E12=""),"FEHLER: Stangenlänge fehlt","OK"))))))
I13: =IF(A13&B13="","",IF(ISNA(MATCH(A13,lst_Profil,0)),"FEHLER: Profil unbekannt",IF(ISNA(MATCH(B13,lst_Werkstoff,0)),"FEHLER: Werkstoff unbekannt",IF(COUNTIFS($A$5:$A$304,A13,$B$5:$B$304,B13)>1,"FEHLER: doppelt",IF(OR(C13="",D13=""),"FEHLER: Preis unvollständig",IF(AND(C13="€/Stange",E13=""),"FEHLER: Stangenlänge fehlt","OK"))))))
I14: =IF(A14&B14="","",IF(ISNA(MATCH(A14,lst_Profil,0)),"FEHLER: Profil unbekannt",IF(ISNA(MATCH(B14,lst_Werkstoff,0)),"FEHLER: Werkstoff unbekannt",IF(COUNTIFS($A$5:$A$304,A14,$B$5:$B$304,B14)>1,"FEHLER: doppelt",IF(OR(C14="",D14=""),"FEHLER: Preis unvollständig",IF(AND(C14="€/Stange",E14=""),"FEHLER: Stangenlänge fehlt","OK"))))))
I15: =IF(A15&B15="","",IF(ISNA(MATCH(A15,lst_Profil,0)),"FEHLER: Profil unbekannt",IF(ISNA(MATCH(B15,lst_Werkstoff,0)),"FEHLER: Werkstoff unbekannt",IF(COUNTIFS($A$5:$A$304,A15,$B$5:$B$304,B15)>1,"FEHLER: doppelt",IF(OR(C15="",D15=""),"FEHLER: Preis unvollständig",IF(AND(C15="€/Stange",E15=""),"FEHLER: Stangenlänge fehlt","OK"))))))
I16: =IF(A16&B16="","",IF(ISNA(MATCH(A16,lst_Profil,0)),"FEHLER: Profil unbekannt",IF(ISNA(MATCH(B16,lst_Werkstoff,0)),"FEHLER: Werkstoff unbekannt",IF(COUNTIFS($A$5:$A$304,A16,$B$5:$B$304,B16)>1,"FEHLER: doppelt",IF(OR(C16="",D16=""),"FEHLER: Preis unvollständig",IF(AND(C16="€/Stange",E16=""),"FEHLER: Stangenlänge fehlt","OK"))))))
